# 8. 비동기 처리

- [8. 비동기 처리](#8-비동기-처리)
  - [8.3 프로미스 사용하기](#83-프로미스-사용하기)
    - [8.3.8 프로미스 체인 (1) 체인 만들기](#838-프로미스-체인-1-체인-만들기)
    - [8.3.9 프로미스 체인 (2) 연쇄적인 비동기 처리](#839-프로미스-체인-2-연쇄적인-비동기-처리)
    - [8.3.10 프로미스 체인 (3) 에러 처리](#8310-프로미스-체인-3-에러-처리)
    - [8.3.11 dynamic import 구문](#8311-dynamic-import-구문)

## 8.3 프로미스 사용하기

### 8.3.8 프로미스 체인 (1) 체인 만들기

then, catch, finally 메서드 => 새로운 프로미스 객체를 만듦

```ts
import { readFile } from 'fs/promises';

const p = readFile('foo.txt', 'utf8');

const p2 = p.then((result) => result + result);

p2.then((result) => {
  console.log(result);
});
```

=> p.then으로 만들어진 새로운 프로미스 p2. p.then에 전달한 콜백 함수가 반환값을 지님.  
콜백 함수가 바로(동기적으로) 결과가 나오므로 p가 완료되면 p2도 완료되면서 등록된 콜백 함수가 실행됨.

p가 실패하면 p.then의 콜백 함수는 호출되지 않고, 이 실패가 전파되며 p2도 같이 실패하게 됨.

```ts
import { readFile } from 'fs/promises';

const p = readFile('foo.txt', 'utf8');

const p2 = p.catch(() => '');

p2.then((result) => {
  console.log(result);
});
```

=> p.catch로 전달된 콜백 함수는 p가 실패했을 때 호출.  
p2는 이 콜백 함수의 반환값을 결과로 삼아 성공하게 됨 => catch가 프로미스의 실패를 성공으로 변환할 수 있음

p는 실패하지만, p2는 성공하게 된 것
p가 성공하면, p.catch로 등록된 콜백 함수는 호출되지 않고 p2도 곧바로 성공함  
=> p가 성공하든 실패하든 관계없이 p2는 성공함

```ts
import { readFile } from 'fs/promises';

readFile('foo.txt', 'utf8')
  .catch(() => '')
  .then((result) => {
    console.log(result);
  });
```

=> 주된 목적이 결과 변환이라면 굳이 변수에 넣지 않고 then이나 catch를 직접 호출.  
=> 프로미스 체인

```ts
readFile('foo.txt', 'utf8')
  .finally(() => {
    console.log('foo.txt is loaded?');
  })
  .catch(() => '')
  .then((result) => {
    console.log(result);
  });
```

=> finally 메서드 결과도 새로운 프로미스. finally의 콜백 함수는 그 반환값이 프로미스의 결과에 영향을 미치지는 않음

### 8.3.9 프로미스 체인 (2) 연쇄적인 비동기 처리

프로미스 체인의 진가는 '연쇄적인 비동기 처리'에서 발휘.

```ts
const repeat10 = (str: string) =>
  new Promise<string>((resolve) => {
    setTimeout(() => resolve(str.repeat(10)), 1000);
  });
```

=> readFile의 결과를 10회 반복시킨 문자열 만듦. 성공적으로 읽어들이면 1초 후에 문자열이 출력됨

```ts
readFile('foo.txt', 'utf8')
  .then((result) => repeat10(result))
  .then((result) => {
    console.log(result);
  });
```

=> then의 콜백 함수가 프로미스를 반환.

```ts
const p1 = readFile('foo.txt', 'utf8');
const p3 = p1.then((result) => {
  const p2 = repeat10(result);
  return p2;
});
p3.then((result) => {
  console.log(result);
});
```

=> 4개의 프로미스로 분해.

프로미스가 중첩되는 일은 없음. 반환된 p2의 결과가 그대로 p3의 결과로서 채택됨.  
p2의 결과가 1초 걸리니 p3의 결과도 1초 후가 됨.  
=> 파일 읽기가 완료되고 1초 후에 p3.then의 콜백 함수가 실행됨

then의 콜백 함수가 반환값으로 프로미스를 반환한다는 점을 이용해 then으로 만들어진 프로미스 완료를 늦출 수 있음.

p1.then의 콜백이 프로미스 p2를 반환함으로써 p2와 p3의 결과가 동일해지고  
p3의 결과는 p2의 결과가 나올 때까지 지연됨.  
(catch, finally의 경우도 동일)

readFile, repeat10이라는 두 개의 비동기 처리를 순서대로 실행한 것  
후자의 비동기 처리에는 전자의 결과가 사용되기 때문에 순서대로 실행해야 했기 때문.

### 8.3.10 프로미스 체인 (3) 에러 처리

성공한 프로미스를 실패로 변환할 수도 있음. 콜백 함수 내부에서 에러 발생 시키면 됨

```ts
import { readFile } from 'fs/promises';

const p1 = readFile('foo.txt', 'utf8');
const p2 = p1.then((result) => {
  throw new Error('Error!!!!');
});
p2.then((result) => {
  console.log(result);
});
```

=> p1 성공하면 then 콜백 함수 호출하고 throw 문으로 에러 발생 간주되어 실패 야기함  
=> p2의 결과는 실패가 되고 p2.then의 콜백 함수는 호출되지 않음

```ts
const sleepReject = (duration: number) => {
  return new Promise<never>((resolve, reject) => {
    setTimeout(reject, duration);
  });
};

const p = readFile('foo.txt', 'utf8')
  .then(() => sleepReject(1000))
  .then(
    (result) => {
      console.log(result);
    },
    () => {
      console.log('실패했습니다');
    }
  );
```

=> 파일 읽기 완료되고 1초 후에 then이 반환한 프로미스가 실패하면서 '실패했습니다' 출력.

```ts
const p = readFile('foo.txt', 'utf8')
  .then(() => sleepReject(1000))
  .then((result) => {
    console.log(result);
  });
```

=> then의 두 번째 콜백 함수를 넣지 않으면?  
에러 메시지 출력되며 프로세스 강제 종료됨  
=> 프로미스의 에러가 핸들링 되지 않았을 경우에 출력되는 에러(실패한 프로미스에 콜백 함수가 아무것도 등록되지 않았을 경우)

실패할 가능성이 있는 프로미스는 반드시 catch 등으로 에러 처리를 수행(실패한 프로미스를 방치하지 않고 성공으로 변환)해야 함

```ts
import { readFile } from 'fs/promises';

const p = readFile('foo.txt', 'utf8');

p.then((result) => {
  console.log('성공', result);
});
p.catch((error) => {
  console.log('실패', error);
});
```

```ts
import { readFile } from 'fs/promises';

const p = readFile('foo.txt', 'utf8');

const p2 = p.then((result) => {
  console.log('성공', result);
});
const p3 = p.catch((error) => {
  console.log('실패', error);
});
```

=> 실패하면 UnhandledPromiseRejection 에러 추가 발생.  
p가 실패하면 p2로 전파되어 p2가 실패함. p2에는 콜백 함수가 등록되어 있지 않음.  
하나의 프로미스 p에 then과 catch를 따로 호출해서는 안됨.

```ts
import { readFile } from 'fs/promises';

const p = readFile('foo.txt', 'utf8');

const p2 = p.then((result) => {
  console.log('성공', result);
});
const p3 = p2.catch((error) => {
  console.log('실패', error);
});
```

=> p가 성공하면 p.then의 콜백 함수 실행, p가 실패하면 그 실패는 p2로 전파되어 p2의 콜백 함수가 실행됨

### 8.3.11 dynamic import 구문

dynamic import 구문은 `import("모듈명")`으로 함수 호출과 같은 형태를 띠며, 지정한 모듈을 비동기적으로 불러올 수 있음

보통의 import 선언과 다른 점은 dynamic import가 실행되기까지 모듈이 불러와지지 않는다는 점.  
보통의 import 선언에서는 import하는 쪽의 모듈이 실행되기 전에 import된 모듈의 불러오기 실행이 완료됨.  
dynamic import는 해당 모듈이 필요해지기 전까지는 불러오고 싶지 않은 경우(지연 로드) 유용.

모듈을 dynamic import로 가져올 경우에는 비동기로 처리. 따라서 결과는 프로미스. 프로미스의 결과는 해당 모듈의 네임스페이스 객체.

```ts
import('fs/promises')
  .then(({ readFile }) => readFile('foo.txt', 'utf8'))
  .then((result) => {
    console.log(result);
  })
  .catch((error) => {
    console.log('에러가 발생했습니다!!!!', error);
  });
```

=> fs/promises 모듈을 dynamic import로 가져와서 파일을 불러옴

`import("fs/promises")`로 결과가 fs/promises의 네임스페이스 객체인 프로미스를 가져옴. 그 다음의 then에서는 분해 할당으로 네임스페이스 객체로부터 readFile을 가져온 뒤, readFile로부터 얻은 프로미스를 반환함
